start complete
Initiating game:  PandaReach-v3
Experiments starting for:  ConTest1
Traceback (most recent call last):
  File "/home/user/.local/lib/python3.8/site-packages/pandas/core/indexes/base.py", line 3361, in get_loc
    return self._engine.get_loc(casted_key)
  File "pandas/_libs/index.pyx", line 76, in pandas._libs.index.IndexEngine.get_loc
  File "pandas/_libs/index.pyx", line 108, in pandas._libs.index.IndexEngine.get_loc
  File "pandas/_libs/hashtable_class_helper.pxi", line 5198, in pandas._libs.hashtable.PyObjectHashTable.get_item
  File "pandas/_libs/hashtable_class_helper.pxi", line 5206, in pandas._libs.hashtable.PyObjectHashTable.get_item
KeyError: 'invalid11210'
The above exception was the direct cause of the following exception:
Traceback (most recent call last):
  File "/home/user/Thesis/trial.py", line 124, in start
    self.run()
  File "/home/user/Thesis/trial.py", line 141, in run
    self.take_step()
  File "/home/user/Thesis/trial.py", line 312, in take_step
    envState = self.agent.step(self.humanAction, self.humanFeedback)
  File "/home/user/Thesis/agent.py", line 311, in step
    self.q_sa, self.max_q_sa = self.Qagent.learning(human_action, reward, self.last_state, next_state)
  File "/home/user/Thesis/Q_Learning.py", line 34, in learning
    max_next_q_sa = self.qtable.loc[next_state, :].max()
  File "/home/user/.local/lib/python3.8/site-packages/pandas/core/indexing.py", line 925, in __getitem__
    return self._getitem_tuple(key)
  File "/home/user/.local/lib/python3.8/site-packages/pandas/core/indexing.py", line 1100, in _getitem_tuple
    return self._getitem_lowerdim(tup)
  File "/home/user/.local/lib/python3.8/site-packages/pandas/core/indexing.py", line 838, in _getitem_lowerdim
    section = self._getitem_axis(key, axis=i)
  File "/home/user/.local/lib/python3.8/site-packages/pandas/core/indexing.py", line 1164, in _getitem_axis
    return self._get_label(key, axis=axis)
  File "/home/user/.local/lib/python3.8/site-packages/pandas/core/indexing.py", line 1113, in _get_label
    return self.obj.xs(label, axis=axis)
  File "/home/user/.local/lib/python3.8/site-packages/pandas/core/generic.py", line 3776, in xs
    loc = index.get_loc(key)
  File "/home/user/.local/lib/python3.8/site-packages/pandas/core/indexes/base.py", line 3363, in get_loc
    raise KeyError(key) from err
KeyError: 'invalid11210'
Traceback (most recent call last):
  File "/home/user/.local/lib/python3.8/site-packages/pandas/core/indexes/base.py", line 3361, in get_loc
    return self._engine.get_loc(casted_key)
  File "pandas/_libs/index.pyx", line 76, in pandas._libs.index.IndexEngine.get_loc
  File "pandas/_libs/index.pyx", line 108, in pandas._libs.index.IndexEngine.get_loc
  File "pandas/_libs/hashtable_class_helper.pxi", line 5198, in pandas._libs.hashtable.PyObjectHashTable.get_item
  File "pandas/_libs/hashtable_class_helper.pxi", line 5206, in pandas._libs.hashtable.PyObjectHashTable.get_item
KeyError: 'invalid11210'
The above exception was the direct cause of the following exception:
Traceback (most recent call last):
  File "/home/user/Thesis/trial.py", line 124, in start
    self.run()
  File "/home/user/Thesis/trial.py", line 141, in run
    self.take_step()
  File "/home/user/Thesis/trial.py", line 312, in take_step
    envState = self.agent.step(self.humanAction, self.humanFeedback)
  File "/home/user/Thesis/agent.py", line 311, in step
    self.q_sa, self.max_q_sa = self.Qagent.learning(human_action, reward, self.last_state, next_state)
  File "/home/user/Thesis/Q_Learning.py", line 34, in learning
    max_next_q_sa = self.qtable.loc[next_state, :].max()
  File "/home/user/.local/lib/python3.8/site-packages/pandas/core/indexing.py", line 925, in __getitem__
    return self._getitem_tuple(key)
  File "/home/user/.local/lib/python3.8/site-packages/pandas/core/indexing.py", line 1100, in _getitem_tuple
    return self._getitem_lowerdim(tup)
  File "/home/user/.local/lib/python3.8/site-packages/pandas/core/indexing.py", line 838, in _getitem_lowerdim
    section = self._getitem_axis(key, axis=i)
  File "/home/user/.local/lib/python3.8/site-packages/pandas/core/indexing.py", line 1164, in _getitem_axis
    return self._get_label(key, axis=axis)
  File "/home/user/.local/lib/python3.8/site-packages/pandas/core/indexing.py", line 1113, in _get_label
    return self.obj.xs(label, axis=axis)
  File "/home/user/.local/lib/python3.8/site-packages/pandas/core/generic.py", line 3776, in xs
    loc = index.get_loc(key)
  File "/home/user/.local/lib/python3.8/site-packages/pandas/core/indexes/base.py", line 3363, in get_loc
    raise KeyError(key) from err
KeyError: 'invalid11210'
envAction: [-1, 0, 0]
envActionNeg: [1, 0, 0]